<?xml version="1.0"?>
<robot xmlns:xacro="http://www.ros.org/wiki/xacro" name="bot">


<!--Colors-->
<material name="blue">
    <color rgba="0 0 1.0 1.0"/>
</material>



<!--  Chassis -->
    <link name="base_link">
        <visual>
            <origin rpy="0  0  0" xyz="0  0  0.2"/>
            <geometry>
                <box size="1 0.5 0.3"/>
            </geometry>
            <material name="blue"/>
        </visual>
        <collision>
            <origin rpy="0 0 0" xyz="0 0 0.2"/>
            <geometry>
                <box size="1 0.5 0.3"/>
            </geometry>
        </collision>
        <inertial>
            <mass value="1"/>
            <origin rpy="0  0  0" xyz="0  0  0.2"/>
            <inertia ixx="0.166667" ixy="0" ixz="0" iyy="0.166667" iyz="0" izz="0.166667"/>
        </inertial>
    </link>
    
    


<!-- Wheel 1-->
    <link name="f_left">
        <inertial>
            <mass value="0.01"/>
            <origin xyz="0 0 0" rpy="0 0 0"/>
            <inertia ixx="0.01" ixy="0.0" ixz="0.0" iyy="0.01" iyz="0.0" izz="0.01"/>
        </inertial>
        <visual>
            <origin xyz="0 0 0" rpy="0 0 0"/>
            <geometry>
                <cylinder radius="0.2" length="0.1" />
            </geometry>
        </visual>
        <collision>
            <origin xyz="0 0 0" rpy="0 0 0"/>
            <geometry>
                <cylinder radius="0.2" length="0.1" />
            </geometry>
        </collision>
    </link>

<!--Wheel joint 1-->
    <joint name="j_s1" type="continuous">
        <parent link="base_link"/>
        <child link="f_left"/>
        <origin xyz= "0.35 0.3 0.15" rpy="1.5707963267949 0 0"/>
        <axis xyz="0 0 0.4" rpy="0 0 0"/>
    </joint>

    

<!-- Wheel 2-->
    <link name="f_right">
        <inertial>
            <mass value="0.01"/>
            <origin xyz="0 0 0" rpy="0 0 0"/>
            <inertia ixx="0.01" ixy="0.0" ixz="0.0" iyy="0.01" iyz="0.0" izz="0.01"/>
        </inertial>
        <visual>
            <origin xyz="0 0 0" rpy="0 0 0"/>
            <geometry>
                <cylinder radius="0.2" length="0.1" />
            </geometry>
        </visual>
        <collision>
            <origin xyz="0 0 0" rpy="0 0 0"/>
            <geometry>
                <cylinder radius="0.2" length="0.1" />
            </geometry>
        </collision>
    </link>



<!--Wheel joint 2-->
    <joint name="j_s2" type="continuous">
        <parent link="base_link"/>
        <child link="f_right"/>
        <origin xyz= "0.35 -0.3 0.15" rpy="1.5708 0 0"/>
        <axis xyz="0 0 0.4" rpy="0 0 0"/>
    </joint>



<!-- Wheel 3-->
    <link name="b_left">
        <inertial>
            <mass value="0.01"/>
            <origin xyz="0 0 0" rpy="0 0 0"/>
            <inertia ixx="0.01" ixy="0.0" ixz="0.0" iyy="0.01" iyz="0.0" izz="0.01"/>
        </inertial>
        <visual>
            <origin xyz="0 0 0" rpy="0 0 0"/>
            <geometry>
                <cylinder radius="0.2" length="0.1" />
            </geometry>
        </visual>
        <collision>
            <origin xyz="0 0 0" rpy="0 0 0"/>
            <geometry>
                <cylinder radius="0.2" length="0.1" />
            </geometry>
        </collision>
    </link>


<!--Wheel joint 3-->
    <joint name="j_s3" type="continuous">
        <parent link="base_link"/>
        <child link="b_left"/>
        <origin xyz= "-0.35 0.3 0.15" rpy="1.5708 0 0"/>
        <axis xyz="0 0 0.4" rpy="0 0 0"/>
    </joint>
    


<!-- Wheel 4-->
    <link name="b_right">
        <inertial>
            <mass value="0.01"/>
            <origin xyz="0 0 0" rpy="0 0 0"/>
            <inertia ixx="0.01" ixy="0.0" ixz="0.0" iyy="0.01" iyz="0.0" izz="0.01"/>
        </inertial>
        <visual>
            <origin xyz="0 0 0" rpy="0 0 0"/>
            <geometry>
                <cylinder radius="0.2" length="0.1" />
            </geometry>
        </visual>
        <collision>
            <origin xyz="0 0 0" rpy="0 0 0"/>
            <geometry>
                <cylinder radius="0.2" length="0.1" />
            </geometry>
        </collision>
    </link>
    


<!--Wheel joint 4-->
    <joint name="j_s4" type="continuous">
        <parent link="base_link"/>
        <child link="b_right"/>
        <origin xyz="-0.35 -0.3 0.15" rpy="1.5708 0 0"/>
        <axis xyz="0 0 0.4" rpy="0 0 0"/>
    </joint>




 <!-- Camera -->
    <xacro:property name="camera_link" value="0.05" />
  <link name="camera_link">
    <collision>
      <origin xyz="0 0 0" rpy="0 0 0"/>
      <geometry>
    <box size="${camera_link} ${camera_link} ${camera_link}"/>
      </geometry>
    </collision>

    <visual>
      <origin xyz="0 0 0" rpy="0 0 0"/>
      <geometry>
    <box size="${camera_link} ${camera_link} ${camera_link}"/>
      </geometry>
      <material name="red"/>
    </visual>

    <inertial>
      <mass value="1e-5" />
      <origin xyz="0 0 0" rpy="0 0 0"/>
      <inertia ixx="1e-6" ixy="0" ixz="0" iyy="1e-6" iyz="0" izz="1e-6" />
    </inertial>
  </link>

 <joint name="camera_joint" type="fixed">
    <axis xyz="0 1 0" />
    <origin xyz="0.5 0 0.3" rpy="0 0 0"/>
    <parent link="base_link"/>
    <child link="camera_link"/>
  </joint>

<!-- Camera Plugin -->
  <gazebo reference="camera_link">
    <sensor type="camera" name="camera1">
      <update_rate>30.0</update_rate>
      <camera name="head">
        <horizontal_fov>1.3962634</horizontal_fov>
        <image>
          <width>800</width>
          <height>800</height>
          <format>R8G8B8</format>
        </image>
        <clip>
          <near>0.02</near>
          <far>300</far>
        </clip>
        <noise>
          <type>gaussian</type>
          <!-- Noise is sampled independently per pixel on each frame.
               That pixel's noise value is added to each of its color
               channels, which at that point lie in the range [0,1]. -->
          <mean>0.0</mean>
          <stddev>0.007</stddev>
        </noise>
      </camera>
      <plugin name="camera_controller" filename="libgazebo_ros_camera.so">
        <alwaysOn>true</alwaysOn>
        <updateRate>0.0</updateRate>
        <cameraName>rrbot/camera1</cameraName>
        <imageTopicName>image_raw</imageTopicName>
        <cameraInfoTopicName>camera_info</cameraInfoTopicName>
        <frameName>camera_link</frameName>
        <hackBaseline>0.07</hackBaseline>
        <distortionK1>0.0</distortionK1>
        <distortionK2>0.0</distortionK2>
        <distortionK3>0.0</distortionK3>
        <distortionT1>0.0</distortionT1>
        <distortionT2>0.0</distortionT2>
      </plugin>
    </sensor>
  </gazebo>




<!-- Hokuyo Laser -->

<joint name="hokuyo_joint" type="fixed">
<axis xyz="0 1 0" />
<origin xyz="0 0 0.38" rpy="0 0 0"/>
<parent link="base_link"/>
<child link="hokuyo"/>
</joint>

<link name="hokuyo">
<collision>
  <origin xyz="0 0 0" rpy="0 0 0"/>
  <geometry>
<box size="0.1 0.1 0.1"/>
  </geometry>
</collision>

<visual>
  <origin xyz="0 0 0" rpy="0 0 0"/>
  <geometry>
        <mesh filename="package://robot_struct/meshes/hokuyo.dae"/>
      </geometry>
</visual>

<inertial>
  <mass value="1e-5" />
  <origin xyz="0 0 0" rpy="0 0 0"/>
  <inertia ixx="1e-6" ixy="0" ixz="0" iyy="1e-6" iyz="0" izz="1e-6" />
</inertial>
</link>

<!-- hokuyo plugin -->
  <gazebo reference="hokuyo">
    <sensor type="ray" name="head_hokuyo_sensor"> 
      <pose>0 0 0 0 0 0</pose>
      <visualize>true</visualize>
      <update_rate>40</update_rate>
   <ray>
    <scan>
      <horizontal>
        <samples>720</samples>
        <resolution>1</resolution>
        <min_angle>-1.570796</min_angle>
        <max_angle>1.570796</max_angle>
      </horizontal>
    </scan>
    <range>
      <min>0.10</min>
      <max>30.0</max>
      <resolution>0.01</resolution>
    </range>
    <noise>
      <type>gaussian</type>
      <!-- Noise parameters based on published spec for Hokuyo laser
           achieving "+-30mm" accuracy at range < 10m.  A mean of 0.0m and
           stddev of 0.01m will put 99.7% of samples within 0.03m of the true
           reading. -->
      <mean>0.0</mean>
      <stddev>0.01</stddev>
    </noise>
  </ray>
  <plugin name="gazebo_ros_head_hokuyo_controller" filename="libgazebo_ros_laser.so">
    <topicName>/mybot/laser/scan</topicName>
    <frameName>hokuyo</frameName>
  </plugin>
</sensor>
</gazebo>



<!-- Skid steering drive -->
<gazebo>
  <plugin name="skid_steer_drive_controller" filename="libgazebo_ros_skid_steer_drive.so">
    <updateRate>100.0</updateRate>
    <robotNamespace>/</robotNamespace>
    <leftFrontJoint>j_s1</leftFrontJoint>
    <rightFrontJoint>j_s2</rightFrontJoint>
    <leftRearJoint>j_s3</leftRearJoint>
    <rightRearJoint>j_s4</rightRearJoint>
    <wheelSeparation>0.5</wheelSeparation>
    <wheelDiameter>0.4</wheelDiameter>
    <robotBaseFrame>base_link</robotBaseFrame>
    <torque>20</torque>
    <topicName>cmd_vel</topicName>
    <broadcastTF>false</broadcastTF>
  </plugin>
</gazebo>




</robot>
